Workbook

Sheet 06 Garde Manger
B1: 06 - Garde Manger - 13 - Canapes & Circles 6/01/13 | F1: 06 - Garde Manger - 15 - Menu Basic Preperation 01/06/15 | J1: 06 - Garde Manger - 16 - Liquor, Alcohol, Wine 01/06/16 | N1: 06 - Garde Manger - 10 - Vegeteables & Fruits - 03/06/10 | R1: 06 - Garde Manger - 07 - Meat - 05/06/07 | V1: 06 - Garde Manger - 08 - Fish and Seafood - 05/06/08
B2: Code | C2: Ingredient Name | D2: UM | F2: Code | G2: Ingredient Name | H2: UM | J2: Code | K2: Ingredient Name | L2: UM | N2: Code | O2: Ingredient Name | P2: UM | R2: Code | S2: Ingredient Name | T2: UM | V2: Code | W2: Ingredient Name | X2: UM
B3: 110102 | C3: =VLOOKUP(B3,'FML March 2026'!E:F,2,false) -> AGAVE RAW AMBER MADHAVA | D3: =VLOOKUP(B3,'Unit of Measure ship March 2026'!A:C,3,false) -> LBS | F3: 110017 | G3: =VLOOKUP(F3,'FML March 2026'!E:F,2,false) -> ACAI FRUIT PUREE 60X3.5OZ SAMBAZON | H3: =VLOOKUP(F3,'Unit of Measure ship March 2026'!A:C,3,false) -> LBS | J3: 147985 | K3: 24 JINRO 700 ML CLEAR BOTTLE VV | L3: BTL | N3: 110061 | O3: =VLOOKUP(N3,'FML March 2026'!E:F,2,false) -> APPLES GALA 125 CI | P3: =VLOOKUP(N3,'Unit of Measure ship March 2026'!A:C,3,false) -> LBS | R3: 148887 | S3: =VLOOKUP(R3,'FML March 2026'!E:F,2,false) -> BEEF TENDERLOIN PEELED STRAP-ON 100 DAY GRAIN FED JBS (AUSTRALIA) NAMP-189A | T3: =VLOOKUP(R3,'Unit of Measure ship March 2026'!A:C,3,false) -> LBS | V3: 42269 | W3: =VLOOKUP(V3,'FML March 2026'!E:F,2,false) -> SHRIMP 16/20 RAW P&D TAIL-ON CS10/LB SURAM ROYAL WHITE (VIETNAM) | X3: =VLOOKUP(V3,'Unit of Measure ship March 2026'!A:C,3,false) -> LBS
B4: 111083 | C4: =VLOOKUP(B4,'FML March 2026'!E:F,2,false) -> ALEPPO PEPPER PKG 1/LB LA BOITE | D4: =VLOOKUP(B4,'Unit of Measure ship March 2026'!A:C,3,false) -> LBS | F4: 110102 | G4: =VLOOKUP(F4,'FML March 2026'!E:F,2,false) -> AGAVE RAW AMBER MADHAVA | H4: =VLOOKUP(F4,'Unit of Measure ship March 2026'!A:C,3,false) -> LBS | J4: 20877 | K4: AJI MIRIN (SWEET COOKING RICE WINE) | L4: BTL | N4: 15370 | O4: =VLOOKUP(N4,'FML March 2026'!E:F,2,false) -> APPLES GOLDEN DELICIOUS 125CT WASHINGTON FANCY 40#/CS | P4: =VLOOKUP(N4,'Unit of Measure ship March 2026'!A:C,3,false) -> LBS | R4: 34728 | S4: =VLOOKUP(R4,'FML March 2026'!E:F,2,false) -> BEEF, STRIPLOIN, BONELESS, 13 DWN, UPPER 2/3, CHOICE, ANGUS, 40 DAY AGED, 0X1, NAMP 180, USA ONLY, <22 LB EA, FZN, 3/1 EA | T4: =VLOOKUP(R4,'Unit of Measure ship March 2026'!A:C,3,false) -> LBS | V4: 14686 | W4: =VLOOKUP(V4,'FML March 2026'!E:F,2,false) -> SHRIMP PANDALUS BOREALIS COOKED 150/250 IQF COLD WATER P&D 4/5LB CS ORION/PACKER (CANADA) | X4: =VLOOKUP(V4,'Unit of Measure ship March 2026'!A:C,3,false) -> LBS
B5: 16262 | C5: =VLOOKUP(B5,'FML March 2026'!E:F,2,false) -> ALLSPICE BADIA | D5: =VLOOKUP(B5,'Unit of Measure ship March 2026'!A:C,3,false) -> LBS | F5: 111083 | G5: =VLOOKUP(F5,'FML March 2026'!E:F,2,false) -> ALEPPO PEPPER PKG 1/LB LA BOITE | H5: =VLOOKUP(F5,'Unit of Measure ship March 2026'!A:C,3,false) -> LBS | J5: 10690 | K5: BAILEYS IRISH CREAM | L5: BTL | N5: 23757 | O5: =VLOOKUP(N5,'FML March 2026'!E:F,2,false) -> APPLES GRANNY SMITH 88CT 40#/CS | P5: =VLOOKUP(N5,'Unit of Measure ship March 2026'!A:C,3,false) -> LBS | R5: 11690 | S5: =VLOOKUP(R5,'FML March 2026'!E:F,2,false) -> CHICKEN BREAST, BONELESS, SKINLESS, NON-MARINATED, NON-INJECTED, 6-7 OZ EA, FZN, 1/40 LB | T5: =VLOOKUP(R5,'Unit of Measure ship March 2026'!A:C,3,false) -> LBS | V5: 14651 | W5: =VLOOKUP(V5,'FML March 2026'!E:F,2,false) -> TUNA LOIN SKINLESS FROZEN, (IP IS FTZ) (YEMEN) | X5: =VLOOKUP(V5,'Unit of Measure ship March 2026'!A:C,3,false) -> LBS
B6: 109664 | C6: =VLOOKUP(B6,'FML March 2026'!E:F,2,false) -> APPLE CIDER VINEGAR SPARROW LANE V | D6: =VLOOKUP(B6,'Unit of Measure ship March 2026'!A:C,3,false) -> GAL | F6: 109224 | G6: =VLOOKUP(F6,'FML March 2026'!E:F,2,false) -> ALMOND BUTTER VEGAN ONCE AGAIN CS6/12 OZ (USA) | H6: =VLOOKUP(F6,'Unit of Measure ship March 2026'!A:C,3,false) -> PC 12/OZ | J6: 110724 | K6: BEER - GOOSE ISLAND IPA BOTTLE 330ML OCI - RSSC VV | L6: BTL | N6: 15375 | O6: =VLOOKUP(N6,'FML March 2026'!E:F,2,false) -> APPLES RED DELICIOUS WASHINGTON EXTRA FANCY 125CT 40#/CS | P6: =VLOOKUP(N6,'Unit of Measure ship March 2026'!A:C,3,false) -> LBS | R6: 11695 | S6: =VLOOKUP(R6,'FML March 2026'!E:F,2,false) -> CHICKEN LEG/THIGH BONELESS & SKINLESS FROZEN | T6: =VLOOKUP(R6,'Unit of Measure ship March 2026'!A:C,3,false) -> LBS
B7: 15651 | C7: =VLOOKUP(B7,'FML March 2026'!E:F,2,false) -> BAKING POWDER 50 LB | D7: =VLOOKUP(B7,'Unit of Measure ship March 2026'!A:C,3,false) -> LBS | F7: 14978 | G7: =VLOOKUP(F7,'FML March 2026'!E:F,2,false) -> AMERICAN CHEESE, YELLOW, SLICED, STACK PACK | H7: =VLOOKUP(F7,'Unit of Measure ship March 2026'!A:C,3,false) -> LBS | J7: 107283 | K7: BEER CIDER DRY STRONGBOW GOLD BREWLOCK KEG 20 LTR VV | L7: BTL | N7: 24182 | O7: =VLOOKUP(N7,'FML March 2026'!E:F,2,false) -> ARUGULA, BABY | P7: =VLOOKUP(N7,'Unit of Measure ship March 2026'!A:C,3,false) -> LBS | R7: 14576 | S7: =VLOOKUP(R7,'FML March 2026'!E:F,2,false) -> CHICKEN, FRYER, WOG, IND WRAPPED, NON-INJECTED, 2.50-3.25 LB EA, FZN, 12/1 EA | T7: =VLOOKUP(R7,'Unit of Measure ship March 2026'!A:C,3,false) -> LBS
B8: 16250 | C8: =VLOOKUP(B8,'FML March 2026'!E:F,2,false) -> BAY LEAVES WHOLE D`ALLESANDRO/ SPICECO | D8: =VLOOKUP(B8,'Unit of Measure ship March 2026'!A:C,3,false) -> LBS | F8: 16013 | G8: =VLOOKUP(F8,'FML March 2026'!E:F,2,false) -> ANCHOVY PASTE 12/1 LB ROLAND | H8: =VLOOKUP(F8,'Unit of Measure ship March 2026'!A:C,3,false) -> CAN/1LB | J8: 111289 | K8: BOURBON BUFFALO TRACE 1LTR RCI VV NCL (USA ) | L8: BTL | N8: 15572 | O8: =VLOOKUP(N8,'FML March 2026'!E:F,2,false) -> ASPARAGUS, FRESH, LARGE, FULL 11# BOX, 17 PC/BOX | P8: =VLOOKUP(N8,'Unit of Measure ship March 2026'!A:C,3,false) -> LBS | R8: 24773 | S8: =VLOOKUP(R8,'FML March 2026'!E:F,2,false) -> PORK BELLY RAW RIND-ON (USA) | T8: =VLOOKUP(R8,'Unit of Measure ship March 2026'!A:C,3,false) -> LBS
B9: 32730 | C9: =VLOOKUP(B9,'FML March 2026'!E:F,2,false) -> BEANS BLACK, 6/#10 CAN | D9: =VLOOKUP(B9,'Unit of Measure ship March 2026'!A:C,3,false) -> CN/6.5LB | F9: 109664 | G9: =VLOOKUP(F9,'FML March 2026'!E:F,2,false) -> APPLE CIDER VINEGAR SPARROW LANE V | H9: =VLOOKUP(F9,'Unit of Measure ship March 2026'!A:C,3,false) -> GAL | J9: 112300 | K9: BRANDY - CHRISTIAN BROTHERS 1LTR (VV) | L9: BTL | N9: 15378 | O9: =VLOOKUP(N9,'FML March 2026'!E:F,2,false) -> AVOCADOS HASS FRESH CA-48PC FL-12/14PC 20# | P9: =VLOOKUP(N9,'Unit of Measure ship March 2026'!A:C,3,false) -> LBS | R9: 14399 | S9: =VLOOKUP(R9,'FML March 2026'!E:F,2,false) -> PORK LOIN WHOLE CRYOVAC 22-24 DOWN BONE IN, NAMP411 (USA) | T9: =VLOOKUP(R9,'Unit of Measure ship March 2026'!A:C,3,false) -> LBS
B10: 16015 | C10: =VLOOKUP(B10,'FML March 2026'!E:F,2,false) -> CAPERS, NON-PAREIL, IN VINEGAR, DRY, 6X850GR | D10: =VLOOKUP(B10,'Unit of Measure ship March 2026'!A:C,3,false) -> CAN/32OZ | F10: 15910 | G10: =VLOOKUP(F10,'FML March 2026'!E:F,2,false) -> BAGELS, PLAIN SLICED 4 OZ SLICED O`PELLE (USA) | H10: =VLOOKUP(F10,'Unit of Measure ship March 2026'!A:C,3,false) -> EA | J10: 10742 | K10: CHAMBORD 750ML OCI-RSSC | L10: BTL | N10: 111708 | O10: =VLOOKUP(N10,'FML March 2026'!E:F,2,false) -> BABY TURNIP | P10: =VLOOKUP(N10,'Unit of Measure ship March 2026'!A:C,3,false) -> LBS
B11: 111930 | C11: =VLOOKUP(B11,'FML March 2026'!E:F,2,false) -> CHEESE OAXACA FRESH CS2/5LB SUPREMO VV | D11: =VLOOKUP(B11,'Unit of Measure ship March 2026'!A:C,3,false) -> LBS | F11: 16250 | G11: =VLOOKUP(F11,'FML March 2026'!E:F,2,false) -> BAY LEAVES WHOLE D`ALLESANDRO/ SPICECO | H11: =VLOOKUP(F11,'Unit of Measure ship March 2026'!A:C,3,false) -> LBS | J11: 24137 | K11: COOKING WINE MOLINOS DE DULCINEA WHITE SPAIN 4/5 LTR APV GAL OCI/ RSSC | L11: LTR | N11: 43516 | O11: =VLOOKUP(N11,'FML March 2026'!E:F,2,false) -> BANANAS STAGE #3 | P11: =VLOOKUP(N11,'Unit of Measure ship March 2026'!A:C,3,false) -> LBS
B12: 16288 | C12: =VLOOKUP(B12,'FML March 2026'!E:F,2,false) -> CORIANDER WHOLE BADIA (USA ) | D12: =VLOOKUP(B12,'Unit of Measure ship March 2026'!A:C,3,false) -> LBS | F12: 26627 | G12: =VLOOKUP(F12,'FML March 2026'!E:F,2,false) -> BEANS CHICK PEAS DRY BULK | H12: =VLOOKUP(F12,'Unit of Measure ship March 2026'!A:C,3,false) -> LBS | J12: 24136 | K12: COOKING WINE RED MOLINOS DE DULCINEA SPAIN 4/5 LTR APV GAL OCI/ RSSC | L12: LTR | N12: 43517 | O12: =VLOOKUP(N12,'FML March 2026'!E:F,2,false) -> BANANAS STAGE #5 | P12: =VLOOKUP(N12,'Unit of Measure ship March 2026'!A:C,3,false) -> LBS
B13: 11882 | C13: =VLOOKUP(B13,'FML March 2026'!E:F,2,false) -> CREME FRAICHE | D13: =VLOOKUP(B13,'Unit of Measure ship March 2026'!A:C,3,false) -> QRT | F13: 111962 | G13: =VLOOKUP(F13,'FML March 2026'!E:F,2,false) -> BOQUERONE IN VINEGAR | H13: =VLOOKUP(F13,'Unit of Measure ship March 2026'!A:C,3,false) -> LBS | J13: 10914 | K13: CORONA EXTRA MEX.BEER BOTTLES 12 OZ RSSC/OCI VV (MEXICO) | L13: BTL | N13: 15429 | O13: =VLOOKUP(N13,'FML March 2026'!E:F,2,false) -> BASIL (12 BUNCH) HYDROPONIC OR REGULAR 1 LB/CS | P13: =VLOOKUP(N13,'Unit of Measure ship March 2026'!A:C,3,false) -> LBS
B14: 16264 | C14: =VLOOKUP(B14,'FML March 2026'!E:F,2,false) -> CUMIN SEED WHOLE BADIA (USA ) | D14: =VLOOKUP(B14,'Unit of Measure ship March 2026'!A:C,3,false) -> LBS | F14: 109712 | G14: =VLOOKUP(F14,'FML March 2026'!E:F,2,false) -> BREAD SOURDOUGH COUNTRY WHEAT BRD40B19 1KG LOAF ZAK THE BAKER | H14: =VLOOKUP(F14,'Unit of Measure ship March 2026'!A:C,3,false) -> LV | J14: 112970 | K14: FILTHY BLOODY MARY MIX | L14: BTL | N14: 111119 | O14: =VLOOKUP(N14,'FML March 2026'!E:F,2,false) -> BASIL BLOSSOMS FRESH TRAY 6/POTS HARPKE FARMS | P14: =VLOOKUP(N14,'Unit of Measure ship March 2026'!A:C,3,false) -> LBS
B15: 16257 | C15: =VLOOKUP(B15,'FML March 2026'!E:F,2,false) -> CURRY POWDER BADIA (USA ) | D15: =VLOOKUP(B15,'Unit of Measure ship March 2026'!A:C,3,false) -> LBS | F15: 16981 | G15: =VLOOKUP(F15,'FML March 2026'!E:F,2,false) -> BRIE MON PERE 60% 3KG / DEXPA # 53726 | H15: =VLOOKUP(F15,'Unit of Measure ship March 2026'!A:C,3,false) -> LBS | J15: 10920 | K15: GOSLINGS GINGER BEER CAN 24/12OZ RSSC/OCI RCCL (BERMUDA) | L15: BTL | N15: 15605 | O15: =VLOOKUP(N15,'FML March 2026'!E:F,2,false) -> BEANS FRESH EXTRA FINE GREEN (FRENCH) 1/5 (HARICOT VERT) | P15: =VLOOKUP(N15,'Unit of Measure ship March 2026'!A:C,3,false) -> LBS
B16: 15026 | C16: =VLOOKUP(B16,'FML March 2026'!E:F,2,false) -> EGGS, WHOLE, LIQUID, W/ CITRIC ACID, NO SUGAR, 1-5 LB/1-5 LT, FZN, 6/5 LB | D16: =VLOOKUP(B16,'Unit of Measure ship March 2026'!A:C,3,false) -> LBS | F16: 15016 | G16: =VLOOKUP(F16,'FML March 2026'!E:F,2,false) -> BUTTER, UNSALTED, 82% FAT, FZN, 50/200 G | H16: =VLOOKUP(F16,'Unit of Measure ship March 2026'!A:C,3,false) -> LBS | J16: 10658 | K16: GRAND MARNIER | L16: BTL | N16: 15449 | O16: =VLOOKUP(N16,'FML March 2026'!E:F,2,false) -> BEET ROOTS LARGE 1/25# | P16: =VLOOKUP(N16,'Unit of Measure ship March 2026'!A:C,3,false) -> LBS
B17: 16259 | C17: =VLOOKUP(B17,'FML March 2026'!E:F,2,false) -> FENNEL SEED WHOLE BADIA (USA ) | D17: =VLOOKUP(B17,'Unit of Measure ship March 2026'!A:C,3,false) -> LBS | F17: 14893 | G17: =VLOOKUP(F17,'FML March 2026'!E:F,2,false) -> BUTTERMILK LOCAL 10 DAYS CS9/HGAL | H17: =VLOOKUP(F17,'Unit of Measure ship March 2026'!A:C,3,false) -> QRT | J17: 10866 | K17: HEINEKEN BEER BOTTLES | L17: BTL | N17: 15333 | O17: =VLOOKUP(N17,'FML March 2026'!E:F,2,false) -> BLACKBERRIES FRESH 12 1/2 PT 4.5# | P17: =VLOOKUP(N17,'Unit of Measure ship March 2026'!A:C,3,false) -> LBS
B18: 14990 | C18: =VLOOKUP(B18,'FML March 2026'!E:F,2,false) -> FETA, IN BRINE, TUB | D18: =VLOOKUP(B18,'Unit of Measure ship March 2026'!A:C,3,false) -> LBS | F18: 11938 | G18: =VLOOKUP(F18,'FML March 2026'!E:F,2,false) -> CAPER BERRIES STEMMED 6/64 OZ DEL DESTINO/ ROLAND | H18: =VLOOKUP(F18,'Unit of Measure ship March 2026'!A:C,3,false) -> CAN/64OZ | J18: 10662 | K18: KAHLUA LIQUOR | L18: BTL | N18: 15335 | O18: =VLOOKUP(N18,'FML March 2026'!E:F,2,false) -> BLUEBERRIES FRESH 12 1/2 PT 4.5# | P18: =VLOOKUP(N18,'Unit of Measure ship March 2026'!A:C,3,false) -> LBS
B19: 31226 | C19: =VLOOKUP(B19,'FML March 2026'!E:F,2,false) -> FLEUR DE SEL / SEL DE GUERANDE 1 KG PAIL | D19: =VLOOKUP(B19,'Unit of Measure ship March 2026'!A:C,3,false) -> LBS | F19: 16015 | G19: =VLOOKUP(F19,'FML March 2026'!E:F,2,false) -> CAPERS, NON-PAREIL, IN VINEGAR, DRY, 6X850GR | H19: =VLOOKUP(F19,'Unit of Measure ship March 2026'!A:C,3,false) -> CAN/32OZ | J19: 112126 | K19: LIQUEUR ABSINTHE VERTE ST. GEORGE 750ML | L19: BTL | N19: 15450 | O19: =VLOOKUP(N19,'FML March 2026'!E:F,2,false) -> BROCCOLI LARGE FANCY, GREEN UMBRELLA 14 CT 20# | P19: =VLOOKUP(N19,'Unit of Measure ship March 2026'!A:C,3,false) -> LBS
B20: 111865 | C20: =VLOOKUP(B20,'FML March 2026'!E:F,2,false) -> FLOUR ALL PURPOSE SIR GALAHAD BAG50/LBS KING ARTHUR | D20: =VLOOKUP(B20,'Unit of Measure ship March 2026'!A:C,3,false) -> LBS | F20: 48393 | G20: =VLOOKUP(F20,'FML March 2026'!E:F,2,false) -> CHAAT MASALA POWDER, INDIAN SPICE 10/100 GR MDH/SHAN | H20: =VLOOKUP(F20,'Unit of Measure ship March 2026'!A:C,3,false) -> LBS | J20: 10685 | K20: LIQUEUR SAMBUCA ROMANA 1LTR OCI/RSSC VV (ITALY ) | L20: BTL | N20: 15454 | O20: =VLOOKUP(N20,'FML March 2026'!E:F,2,false) -> CABBAGE GREEN COMM MED/LG TRIMMED 50# | P20: =VLOOKUP(N20,'Unit of Measure ship March 2026'!A:C,3,false) -> LBS
B21: 112068 | C21: =VLOOKUP(B21,'FML March 2026'!E:F,2,false) -> GOAT CHEESE CHEFS CHEVRE CS 2/4 LB LAUR CHENEL | D21: =VLOOKUP(B21,'Unit of Measure ship March 2026'!A:C,3,false) -> LBS | F21: 14984 | G21: =VLOOKUP(F21,'FML March 2026'!E:F,2,false) -> CHEDDAR BLOCK YELLOW IMP.4/11 | H21: =VLOOKUP(F21,'Unit of Measure ship March 2026'!A:C,3,false) -> LBS | J21: 10427 | K21: MALIBU RUM LIQUEUR | L21: BTL | N21: 15456 | O21: =VLOOKUP(N21,'FML March 2026'!E:F,2,false) -> CABBAGE NAPA 12CT 30# | P21: =VLOOKUP(N21,'Unit of Measure ship March 2026'!A:C,3,false) -> LBS
... B33: 10265 | C33: =VLOOKUP(B33,'FML March 2026'!E:F,2,false) -> OIL, FRYING, 100% SOYBEAN, TRANS FAT FREE, FLASHPOINT >600F, DRY, 4/5 LT | D33: =VLOOKUP(B33,'Unit of Measure ship March 2026'!A:C,3,false) -> CS4/5LT | F33: 14987 | G33: =VLOOKUP(F33,'FML March 2026'!E:F,2,false) -> CREAM CHEESE QUESCREM/PHILADELPHIA FOR BAKERY | H33: =VLOOKUP(F33,'Unit of Measure ship March 2026'!A:C,3,false) -> LBS | J33: 111535 | K33: YAMAHAI JUNMAI, HAPPY OWL FUKU CHITOSE 720ML VV (B) | L33: BTL | N33: 15438 | O33: =VLOOKUP(N33,'FML March 2026'!E:F,2,false) -> CHIVES (12 BUNCH), 1 LB/CS | P33: =VLOOKUP(N33,'Unit of Measure ship March 2026'!A:C,3,false) -> LBS
B34: 52603 | C34: =VLOOKUP(B34,'FML March 2026'!E:F,2,false) -> OLIVE/CANOLA BLEND OIL | D34: =VLOOKUP(B34,'Unit of Measure ship March 2026'!A:C,3,false) -> LT | F34: 11882 | G34: =VLOOKUP(F34,'FML March 2026'!E:F,2,false) -> CREME FRAICHE | H34: =VLOOKUP(F34,'Unit of Measure ship March 2026'!A:C,3,false) -> QRT | N34: 15431 | O34: =VLOOKUP(N34,'FML March 2026'!E:F,2,false) -> CILANTRO (12 BUNCH) 1 LB/CS DOMESTIC | P34: =VLOOKUP(N34,'Unit of Measure ship March 2026'!A:C,3,false) -> LBS
B35: 16439 | C35: =VLOOKUP(B35,'FML March 2026'!E:F,2,false) -> PAN SPRAY NON STICK (USA) | D35: =VLOOKUP(B35,'Unit of Measure ship March 2026'!A:C,3,false) -> CAN/14OZ | F35: 16256 | G35: =VLOOKUP(F35,'FML March 2026'!E:F,2,false) -> CUMIN GROUND D`ALLESANDRO/ SPICECO (USA ) | H35: =VLOOKUP(F35,'Unit of Measure ship March 2026'!A:C,3,false) -> LBS | N35: 111175 | O35: =VLOOKUP(N35,'FML March 2026'!E:F,2,false) -> CILANTRO MICRO FRESH HARPKE FAMILY FARM PK/5 OZ PACKED IN 60 OZ SIZE CLAM SHELL | P35: =VLOOKUP(N35,'Unit of Measure ship March 2026'!A:C,3,false) -> EA
B36: 16538 | C36: =VLOOKUP(B36,'FML March 2026'!E:F,2,false) -> PAPADUMS 80 CT | D36: =VLOOKUP(B36,'Unit of Measure ship March 2026'!A:C,3,false) -> PK/200GR | F36: 16264 | G36: =VLOOKUP(F36,'FML March 2026'!E:F,2,false) -> CUMIN SEED WHOLE BADIA (USA ) | H36: =VLOOKUP(F36,'Unit of Measure ship March 2026'!A:C,3,false) -> LBS | N36: 109754 | O36: =VLOOKUP(N36,'FML March 2026'!E:F,2,false) -> CUCUMBER ENGLISH SEEDLESS, LARGE | P36: =VLOOKUP(N36,'Unit of Measure ship March 2026'!A:C,3,false) -> LBS
B37: 112841 | C37: =VLOOKUP(B37,'FML March 2026'!E:F,2,false) -> PEANUT BUTTER CRUNCHY | D37: =VLOOKUP(B37,'Unit of Measure ship March 2026'!A:C,3,false) -> LBS | F37: 15022 | G37: =VLOOKUP(F37,'FML March 2026'!E:F,2,false) -> EGGS-DATED, MEDIUM, REGULAR | H37: =VLOOKUP(F37,'Unit of Measure ship March 2026'!A:C,3,false) -> PC | N37: 15462 | O37: =VLOOKUP(N37,'FML March 2026'!E:F,2,false) -> CUCUMBERS SEEDLESS LARGE, PLASTIC WRAPPED 13# | P37: =VLOOKUP(N37,'Unit of Measure ship March 2026'!A:C,3,false) -> LBS
B38: 33681 | C38: =VLOOKUP(B38,'FML March 2026'!E:F,2,false) -> PEPPER BLACK GROUND BADIA (USA ) | D38: =VLOOKUP(B38,'Unit of Measure ship March 2026'!A:C,3,false) -> LBS | F38: 15026 | G38: =VLOOKUP(F38,'FML March 2026'!E:F,2,false) -> EGGS, WHOLE, LIQUID, W/ CITRIC ACID, NO SUGAR, 1-5 LB/1-5 LT, FZN, 6/5 LB | H38: =VLOOKUP(F38,'Unit of Measure ship March 2026'!A:C,3,false) -> LBS | N38: 30024 | O38: =VLOOKUP(N38,'FML March 2026'!E:F,2,false) -> CURRY LEAVES | P38: =VLOOKUP(N38,'Unit of Measure ship March 2026'!A:C,3,false) -> KG
B39: 16285 | C39: =VLOOKUP(B39,'FML March 2026'!E:F,2,false) -> PEPPERCORN, BLACK, WHOLE, DRY, 6/420 G | D39: =VLOOKUP(B39,'Unit of Measure ship March 2026'!A:C,3,false) -> LBS | F39: 14997 | G39: =VLOOKUP(F39,'FML March 2026'!E:F,2,false) -> EMMENTHAL LOAF / DEXPA # 7290 - 7465 | H39: =VLOOKUP(F39,'Unit of Measure ship March 2026'!A:C,3,false) -> LBS | N39: 15619 | O39: =VLOOKUP(N39,'FML March 2026'!E:F,2,false) -> DAIKON 20#/CS | P39: =VLOOKUP(N39,'Unit of Measure ship March 2026'!A:C,3,false) -> LBS
B40: 15894 | C40: =VLOOKUP(B40,'FML March 2026'!E:F,2,false) -> PISTACHIO NUTS WHOLE SHELLED RAW NUTLAND | D40: =VLOOKUP(B40,'Unit of Measure ship March 2026'!A:C,3,false) -> LBS | F40: 16259 | G40: =VLOOKUP(F40,'FML March 2026'!E:F,2,false) -> FENNEL SEED WHOLE BADIA (USA ) | H40: =VLOOKUP(F40,'Unit of Measure ship March 2026'!A:C,3,false) -> LBS | N40: 15433 | O40: =VLOOKUP(N40,'FML March 2026'!E:F,2,false) -> DILL | P40: =VLOOKUP(N40,'Unit of Measure ship March 2026'!A:C,3,false) -> LBS
B41: 109676 | C41: =VLOOKUP(B41,'FML March 2026'!E:F,2,false) -> PRESERVED LEMON BRINE CAN/ 2KG BELDI | D41: =VLOOKUP(B41,'Unit of Measure ship March 2026'!A:C,3,false) -> LBS | F41: 14990 | G41: =VLOOKUP(F41,'FML March 2026'!E:F,2,false) -> FETA, IN BRINE, TUB | H41: =VLOOKUP(F41,'Unit of Measure ship March 2026'!A:C,3,false) -> LBS | N41: 36433 | O41: =VLOOKUP(N41,'FML March 2026'!E:F,2,false) -> EGGPLANT JAPANESE 10#/CS | P41: =VLOOKUP(N41,'Unit of Measure ship March 2026'!A:C,3,false) -> CS10/LBS
B42: 15897 | C42: =VLOOKUP(B42,'FML March 2026'!E:F,2,false) -> PUMPKIN SEEDS WHOLE SHELLED RAW 10 LB HIALEAH/ D`ALLESANDRO | D42: =VLOOKUP(B42,'Unit of Measure ship March 2026'!A:C,3,false) -> LBS | F42: 111698 | G42: =VLOOKUP(F42,'FML March 2026'!E:F,2,false) -> FRIED SHALLOTS LA RUSTICHELLA | H42: =VLOOKUP(F42,'Unit of Measure ship March 2026'!A:C,3,false) -> LBS | N42: 15464 | O42: =VLOOKUP(N42,'FML March 2026'!E:F,2,false) -> EGGPLANT MEDIUM, 225 - 300 MM | P42: =VLOOKUP(N42,'Unit of Measure ship March 2026'!A:C,3,false) -> LBS
B43: 142891 | C43: =VLOOKUP(B43,'FML March 2026'!E:F,2,false) -> SALT CURING PRAGUE #1 2.5 LB HOOSIER HILL | D43: =VLOOKUP(B43,'Unit of Measure ship March 2026'!A:C,3,false) -> LBS | F43: 16337 | G43: =VLOOKUP(F43,'FML March 2026'!E:F,2,false) -> GARAM MASALA POWDER INDIAN SPICE D`ALLESANDRO/MAYA | H43: =VLOOKUP(F43,'Unit of Measure ship March 2026'!A:C,3,false) -> LBS | N43: 15547 | O43: =VLOOKUP(N43,'FML March 2026'!E:F,2,false) -> FENNEL FRESH CAL. 40# | P43: =VLOOKUP(N43,'Unit of Measure ship March 2026'!A:C,3,false) -> LBS
B44: 16307 | C44: =VLOOKUP(B44,'FML March 2026'!E:F,2,false) -> SALT KOSHER GRANULATED | D44: =VLOOKUP(B44,'Unit of Measure ship March 2026'!A:C,3,false) -> LBS | F44: 16260 | G44: =VLOOKUP(F44,'FML March 2026'!E:F,2,false) -> GARLIC, POWDER, DRY, 12/16 OZ | H44: =VLOOKUP(F44,'Unit of Measure ship March 2026'!A:C,3,false) -> LBS | N44: 30479 | O44: =VLOOKUP(N44,'FML March 2026'!E:F,2,false) -> GALANGAL | P44: =VLOOKUP(N44,'Unit of Measure ship March 2026'!A:C,3,false) -> LBS
B45: 11260 | C45: =VLOOKUP(B45,'FML March 2026'!E:F,2,false) -> SESAME SEED BLACK | D45: =VLOOKUP(B45,'Unit of Measure ship March 2026'!A:C,3,false) -> LBS | F45: 16958 | G45: =VLOOKUP(F45,'FML March 2026'!E:F,2,false) -> GLUTEN FREE BREAD WHITE RICE 6/16 OZ KINNICKKNICK/UDI'S | H45: =VLOOKUP(F45,'Unit of Measure ship March 2026'!A:C,3,false) -> PC/16OZ | N45: 109766 | O45: =VLOOKUP(N45,'FML March 2026'!E:F,2,false) -> GARLIC BLACK PEELED | P45: =VLOOKUP(N45,'Unit of Measure ship March 2026'!A:C,3,false) -> LBS
... B65: 109846 | C65: =VLOOKUP(B65,'FML March 2026'!E:F,2,false) -> YOGURT GREEK BULK | D65: =VLOOKUP(B65,'Unit of Measure ship March 2026'!A:C,3,false) -> LBS | F65: 16426 | G65: =VLOOKUP(F65,'FML March 2026'!E:F,2,false) -> MUSTARD TUB GREY POUPON - DIJON MUSTARD PLAIN (FRANCE) | H65: =VLOOKUP(F65,'Unit of Measure ship March 2026'!A:C,3,false) -> JAR/48OZ | N65: 15489 | O65: =VLOOKUP(N65,'FML March 2026'!E:F,2,false) -> LETTUCE ROMAINE, CAL., CRISP 24HD 38# | P65: =VLOOKUP(N65,'Unit of Measure ship March 2026'!A:C,3,false) -> LBS
F66: 12275 | G66: =VLOOKUP(F66,'FML March 2026'!E:F,2,false) -> MUSTARD BROWN 4/1 GALLON GULDENS (FRANCE) | H66: =VLOOKUP(F66,'Unit of Measure ship March 2026'!A:C,3,false) -> GAL | N66: 15623 | O66: =VLOOKUP(N66,'FML March 2026'!E:F,2,false) -> LETTUCE, MESCLUN 3#/CS | P66: =VLOOKUP(N66,'Unit of Measure ship March 2026'!A:C,3,false) -> LBS
F67: 16320 | G67: =VLOOKUP(F67,'FML March 2026'!E:F,2,false) -> MUSTARD SEED 24 OZ D`ALLESANDRO/ SPICECO | H67: =VLOOKUP(F67,'Unit of Measure ship March 2026'!A:C,3,false) -> LBS | N67: 108947 | O67: =VLOOKUP(N67,'FML March 2026'!E:F,2,false) -> LIMES, FRESH, CAVIAR (FINGER LIMES) | P67: =VLOOKUP(N67,'Unit of Measure ship March 2026'!A:C,3,false) -> LBS
F68: 16350 | G68: =VLOOKUP(F68,'FML March 2026'!E:F,2,false) -> MUSTARD YELLOW, PREPARED, GAL FRENCH`S | H68: =VLOOKUP(F68,'Unit of Measure ship March 2026'!A:C,3,false) -> GAL | N68: 15399 | O68: =VLOOKUP(N68,'FML March 2026'!E:F,2,false) -> LIMES, FRESH, FIRM #1 200CT 40# | P68: =VLOOKUP(N68,'Unit of Measure ship March 2026'!A:C,3,false) -> LBS
F69: 37627 | G69: =VLOOKUP(F69,'FML March 2026'!E:F,2,false) -> NOODLE, VERMICELLI, GLASS NOODLES, PACKER | H69: =VLOOKUP(F69,'Unit of Measure ship March 2026'!A:C,3,false) -> PK/8.8OZ | N69: 19401 | O69: =VLOOKUP(N69,'FML March 2026'!E:F,2,false) -> LOTUS ROOT FRESH | P69: =VLOOKUP(N69,'Unit of Measure ship March 2026'!A:C,3,false) -> LBS
F70: 52602 | G70: =VLOOKUP(F70,'FML March 2026'!E:F,2,false) -> OIL, 100% OLIVE, EXTRA VIRGIN, DRY, 4/5 LT | H70: =VLOOKUP(F70,'Unit of Measure ship March 2026'!A:C,3,false) -> LT | N70: 110068 | O70: =VLOOKUP(N70,'FML March 2026'!E:F,2,false) -> MAITAKE MUSHROOM FRESH | P70: =VLOOKUP(N70,'Unit of Measure ship March 2026'!A:C,3,false) -> LBS
...

Sheet 07 Kitchen Table
B1: 07 - The Kitchen Table - Menu Basic Preperation 01/07/01 | F1: 07 - The Kitchen Table - Vegetables & Fruit 03/07/06 | J1: 07 - The Kitchen Table - Meat 05/07/03 | N1: 07 - The Kitchen Table - Fish & Seafood 05/07/04
B2: Code | C2: Ingredient Name | D2: UM | F2: Code | G2: Ingredient Name | H2: UM | J2: Code | K2: Ingredient Name | L2: UM | N2: Code | O2: Ingredient Name | P2: UM
B3: 16262 | C3: =VLOOKUP(B3,'FML March 2026'!E:F,2,false) -> ALLSPICE BADIA | D3: =VLOOKUP(B3,'Unit of Measure ship March 2026'!A:C,3,false) -> LBS | F3: 110061 | G3: =VLOOKUP(F3,'FML March 2026'!E:F,2,false) -> APPLES GALA 125 CI | H3: =VLOOKUP(F3,'Unit of Measure ship March 2026'!A:C,3,false) -> LBS | J3: 14457 | K3: =VLOOKUP(J3,'FML March 2026'!E:F,2,false) -> BEEF BOTTOM ROUND GOOSENECK, CHOICE NAMP-170 | L3: =VLOOKUP(J3,'Unit of Measure ship March 2026'!A:C,3,false) -> LBS | N3: 10052 | O3: =VLOOKUP(N3,'FML March 2026'!E:F,2,false) -> COD FILLET BERING SEA 16/32 OZ FROZEN (PCH) (CHINA) | P3: =VLOOKUP(N3,'Unit of Measure ship March 2026'!A:C,3,false) -> LBS
B4: 15799 | C4: =VLOOKUP(B4,'FML March 2026'!E:F,2,false) -> ALMONDS SHELLED WHOLE | D4: =VLOOKUP(B4,'Unit of Measure ship March 2026'!A:C,3,false) -> LBS | F4: 15375 | G4: =VLOOKUP(F4,'FML March 2026'!E:F,2,false) -> APPLES RED DELICIOUS WASHINGTON EXTRA FANCY 125CT 40#/CS | H4: =VLOOKUP(F4,'Unit of Measure ship March 2026'!A:C,3,false) -> LBS | J4: 14383 | K4: =VLOOKUP(J4,'FML March 2026'!E:F,2,false) -> BEEF CHUCK SHORT RIB USDA CHOICE (USA) NAMP-130 | L4: =VLOOKUP(J4,'Unit of Measure ship March 2026'!A:C,3,false) -> LBS | N4: 11757 | O4: =VLOOKUP(N4,'FML March 2026'!E:F,2,false) -> FLOUNDER/HAKE/POLLOCK FILLET BREADED/ BATTERED 4 OZ IQF FOR CREW CWS/10 LB NATIONAL (USA) | P4: =VLOOKUP(N4,'Unit of Measure ship March 2026'!A:C,3,false) -> LBS
B5: 14978 | C5: =VLOOKUP(B5,'FML March 2026'!E:F,2,false) -> AMERICAN CHEESE, YELLOW, SLICED, STACK PACK | D5: =VLOOKUP(B5,'Unit of Measure ship March 2026'!A:C,3,false) -> LBS | F5: 24182 | G5: =VLOOKUP(F5,'FML March 2026'!E:F,2,false) -> ARUGULA, BABY | H5: =VLOOKUP(F5,'Unit of Measure ship March 2026'!A:C,3,false) -> LBS | J5: 11189 | K5: =VLOOKUP(J5,'FML March 2026'!E:F,2,false) -> BEEF GROUND CHUCK C.A.B./ ANGUS NAMP 137-2 | L5: =VLOOKUP(J5,'Unit of Measure ship March 2026'!A:C,3,false) -> LBS | N5: 14630 | O5: =VLOOKUP(N5,'FML March 2026'!E:F,2,false) -> MACKEREL WHOLE GUTTED IQF FOR CREW CS/22 LB ALFA (MEXICO) | P5: =VLOOKUP(N5,'Unit of Measure ship March 2026'!A:C,3,false) -> LBS
B6: 110951 | C6: =VLOOKUP(B6,'FML March 2026'!E:F,2,false) -> ANCHOVIES DRIED CS100/4OZ IKAN-TERI*BILIS | D6: =VLOOKUP(B6,'Unit of Measure ship March 2026'!A:C,3,false) -> LBS | F6: 15572 | G6: =VLOOKUP(F6,'FML March 2026'!E:F,2,false) -> ASPARAGUS, FRESH, LARGE, FULL 11# BOX, 17 PC/BOX | H6: =VLOOKUP(F6,'Unit of Measure ship March 2026'!A:C,3,false) -> LBS | J6: 53802 | K6: =VLOOKUP(J6,'FML March 2026'!E:F,2,false) -> BEEF GROUND FINE 80/20 NAMP-136 | L6: =VLOOKUP(J6,'Unit of Measure ship March 2026'!A:C,3,false) -> LBS | N6: 11826 | O6: =VLOOKUP(N6,'FML March 2026'!E:F,2,false) -> MILKFISH BANGUS FROZEN WHOLE GUTTED (USA) | P6: =VLOOKUP(N6,'Unit of Measure ship March 2026'!A:C,3,false) -> LBS
B7: 16011 | C7: =VLOOKUP(B7,'FML March 2026'!E:F,2,false) -> ANCHOVY FILLETS IN OLIVE OIL | D7: =VLOOKUP(B7,'Unit of Measure ship March 2026'!A:C,3,false) -> CAN/28OZ | F7: 43759 | G7: =VLOOKUP(F7,'FML March 2026'!E:F,2,false) -> ASPARAGUS, GREEN, MEDIUM, GRADE A, IQF, FZN, 1/10 KG | H7: =VLOOKUP(F7,'Unit of Measure ship March 2026'!A:C,3,false) -> LBS | J7: 14369 | K7: =VLOOKUP(J7,'FML March 2026'!E:F,2,false) -> BEEF INSIDE TOP ROUND CHOICE UNTRIMMED NAMP-168 EU (USA) | L7: =VLOOKUP(J7,'Unit of Measure ship March 2026'!A:C,3,false) -> LBS | N7: 14793 | O7: =VLOOKUP(N7,'FML March 2026'!E:F,2,false) -> MUSSEL MEAT SMALL NEW ZEALAND/CHILE BLUE IQF FROZEN 200-300 CT GOLDEN SUN (CHILE) | P7: =VLOOKUP(N7,'Unit of Measure ship March 2026'!A:C,3,false) -> LBS
B8: 16013 | C8: =VLOOKUP(B8,'FML March 2026'!E:F,2,false) -> ANCHOVY PASTE 12/1 LB ROLAND | D8: =VLOOKUP(B8,'Unit of Measure ship March 2026'!A:C,3,false) -> CAN/1LB | F8: 15429 | G8: =VLOOKUP(F8,'FML March 2026'!E:F,2,false) -> BASIL (12 BUNCH) HYDROPONIC OR REGULAR 1 LB/CS | H8: =VLOOKUP(F8,'Unit of Measure ship March 2026'!A:C,3,false) -> LBS | J8: 14389 | K8: =VLOOKUP(J8,'FML March 2026'!E:F,2,false) -> BEEF OXTAIL STEER W/LINER U.S.D.A. NAMP -1791 | L8: =VLOOKUP(J8,'Unit of Measure ship March 2026'!A:C,3,false) -> LBS | N8: 49645 | O8: =VLOOKUP(N8,'FML March 2026'!E:F,2,false) -> POLLOCK FILLET 4/8 OZ SKINLESS 100% NET WEIGHT (CHINA) | P8: =VLOOKUP(N8,'Unit of Measure ship March 2026'!A:C,3,false) -> LBS
B9: 16304 | C9: =VLOOKUP(B9,'FML March 2026'!E:F,2,false) -> ANISE STAR BADIA | D9: =VLOOKUP(B9,'Unit of Measure ship March 2026'!A:C,3,false) -> UNIT/8OZ | F9: 102292 | G9: =VLOOKUP(F9,'FML March 2026'!E:F,2,false) -> BEETS YELLOW FRESH | H9: =VLOOKUP(F9,'Unit of Measure ship March 2026'!A:C,3,false) -> LBS | J9: 102748 | K9: =VLOOKUP(J9,'FML March 2026'!E:F,2,false) -> BEEF PATTIES 5.33 OZ CHUCK/BRISKET/SHORT RIB CS/10 LB (USA) NAMP-1137 | L9: =VLOOKUP(J9,'Unit of Measure ship March 2026'!A:C,3,false) -> LBS | N9: 53625 | O9: =VLOOKUP(N9,'FML March 2026'!E:F,2,false) -> SALMON FILLET, ATLANTIC, PREMIUM, FROZEN, 3 - 4 LB D-TRIM INDV. CRYOVAC (CHILE) | P9: =VLOOKUP(N9,'Unit of Measure ship March 2026'!A:C,3,false) -> LBS
B10: 16508 | C10: =VLOOKUP(B10,'FML March 2026'!E:F,2,false) -> APRICOT HALVES, UNPEELED | D10: =VLOOKUP(B10,'Unit of Measure ship March 2026'!A:C,3,false) -> CN/6.5LB | F10: 15452 | G10: =VLOOKUP(F10,'FML March 2026'!E:F,2,false) -> BELGIAN ENDIVES 10# | H10: =VLOOKUP(F10,'Unit of Measure ship March 2026'!A:C,3,false) -> LBS | J10: 38308 | K10: =VLOOKUP(J10,'FML March 2026'!E:F,2,false) -> BEEF, STRIPLOIN, BONELESS, COMMERCIAL, NON-UTILITY, 1X1, NAMP 180, >8 LB EA, FZN, 5/1 EA | L10: =VLOOKUP(J10,'Unit of Measure ship March 2026'!A:C,3,false) -> LBS | N10: 23371 | O10: =VLOOKUP(N10,'FML March 2026'!E:F,2,false) -> SALMON KETA WHOLE H&G FROZEN CREW CS 50/LBS (CHILE) | P10: =VLOOKUP(N10,'Unit of Measure ship March 2026'!A:C,3,false) -> LBS
B11: 19448 | C11: =VLOOKUP(B11,'FML March 2026'!E:F,2,false) -> AVOCADO, HALVES, PITLESS, IQF, FRZN | D11: =VLOOKUP(B11,'Unit of Measure ship March 2026'!A:C,3,false) -> LBS | F11: 15606 | G11: =VLOOKUP(F11,'FML March 2026'!E:F,2,false) -> BOK CHOY BABY | H11: =VLOOKUP(F11,'Unit of Measure ship March 2026'!A:C,3,false) -> LBS | J11: 45649 | K11: =VLOOKUP(J11,'FML March 2026'!E:F,2,false) -> CHICKEN BREAST FILLET, BREADED, FRITTERS, RAW (USA) | L11: =VLOOKUP(J11,'Unit of Measure ship March 2026'!A:C,3,false) -> LBS | N11: 45475 | O11: =VLOOKUP(N11,'FML March 2026'!E:F,2,false) -> SARDINES WHOLE FROZEN NIGEL/PACKER (USA) | P11: =VLOOKUP(N11,'Unit of Measure ship March 2026'!A:C,3,false) -> LBS
B12: 43803 | C12: =VLOOKUP(B12,'FML March 2026'!E:F,2,false) -> BABY CARROTS FROZEN STANDARD DUJARDIN (USA) | D12: =VLOOKUP(B12,'Unit of Measure ship March 2026'!A:C,3,false) -> LBS | F12: 38191 | G12: =VLOOKUP(F12,'FML March 2026'!E:F,2,false) -> BRUSSELS SPROUTS SMALL | H12: =VLOOKUP(F12,'Unit of Measure ship March 2026'!A:C,3,false) -> LBS | J12: 11690 | K12: =VLOOKUP(J12,'FML March 2026'!E:F,2,false) -> CHICKEN BREAST, BONELESS, SKINLESS, NON-MARINATED, NON-INJECTED, 6-7 OZ EA, FZN, 1/40 LB | L12: =VLOOKUP(J12,'Unit of Measure ship March 2026'!A:C,3,false) -> LBS | N12: 33209 | O12: =VLOOKUP(N12,'FML March 2026'!E:F,2,false) -> SEA TROUT FILET 4/6 OZ CREW FROZEN CS/40 LBS (USA) | P12: =VLOOKUP(N12,'Unit of Measure ship March 2026'!A:C,3,false) -> LBS
B13: 12284 | C13: =VLOOKUP(B13,'FML March 2026'!E:F,2,false) -> BARBEQUE SAUCE, HICKORY | D13: =VLOOKUP(B13,'Unit of Measure ship March 2026'!A:C,3,false) -> GAL | F13: 15456 | G13: =VLOOKUP(F13,'FML March 2026'!E:F,2,false) -> CABBAGE NAPA 12CT 30# | H13: =VLOOKUP(F13,'Unit of Measure ship March 2026'!A:C,3,false) -> LBS | J13: 14581 | K13: =VLOOKUP(J13,'FML March 2026'!E:F,2,false) -> CHICKEN LEG QUARTERS FROZEN PACKER (USA) | L13: =VLOOKUP(J13,'Unit of Measure ship March 2026'!A:C,3,false) -> LBS | N13: 42269 | O13: =VLOOKUP(N13,'FML March 2026'!E:F,2,false) -> SHRIMP 16/20 RAW P&D TAIL-ON CS10/LB SURAM ROYAL WHITE (VIETNAM) | P13: =VLOOKUP(N13,'Unit of Measure ship March 2026'!A:C,3,false) -> LBS
B14: 16250 | C14: =VLOOKUP(B14,'FML March 2026'!E:F,2,false) -> BAY LEAVES WHOLE D`ALLESANDRO/ SPICECO | D14: =VLOOKUP(B14,'Unit of Measure ship March 2026'!A:C,3,false) -> LBS | F14: 15455 | G14: =VLOOKUP(F14,'FML March 2026'!E:F,2,false) -> CABBAGE RED COMM MED/LG TRIMMED 50# | H14: =VLOOKUP(F14,'Unit of Measure ship March 2026'!A:C,3,false) -> LBS | J14: 11695 | K14: =VLOOKUP(J14,'FML March 2026'!E:F,2,false) -> CHICKEN LEG/THIGH BONELESS & SKINLESS FROZEN | L14: =VLOOKUP(J14,'Unit of Measure ship March 2026'!A:C,3,false) -> LBS | N14: 14686 | O14: =VLOOKUP(N14,'FML March 2026'!E:F,2,false) -> SHRIMP PANDALUS BOREALIS COOKED 150/250 IQF COLD WATER P&D 4/5LB CS ORION/PACKER (CANADA) | P14: =VLOOKUP(N14,'Unit of Measure ship March 2026'!A:C,3,false) -> LBS
... B18: 16227 | C18: =VLOOKUP(B18,'FML March 2026'!E:F,2,false) -> BEANS LENTILS BLACK BELUGA D`ALLESANDRO | D18: =VLOOKUP(B18,'Unit of Measure ship March 2026'!A:C,3,false) -> LBS | F18: 15562 | G18: =VLOOKUP(F18,'FML March 2026'!E:F,2,false) -> CELERIAC (CELERY ROOT) 20# | H18: =VLOOKUP(F18,'Unit of Measure ship March 2026'!A:C,3,false) -> LBS | J18: 14576 | K18: =VLOOKUP(J18,'FML March 2026'!E:F,2,false) -> CHICKEN, FRYER, WOG, IND WRAPPED, NON-INJECTED, 2.50-3.25 LB EA, FZN, 12/1 EA | L18: =VLOOKUP(J18,'Unit of Measure ship March 2026'!A:C,3,false) -> LBS | N18: 14721 | O18: =VLOOKUP(N18,'FML March 2026'!E:F,2,false) -> WHITING FILET 4/6 OR 6/10 OZ FRZN (ARGENTINA) | P18: =VLOOKUP(N18,'Unit of Measure ship March 2026'!A:C,3,false) -> LBS
B19: 48982 | C19: =VLOOKUP(B19,'FML March 2026'!E:F,2,false) -> BEANS LENTILS RED SPLIT, DHAL MASSOR 20 LB BOX C&F/ D`ALLESANDRO | D19: =VLOOKUP(B19,'Unit of Measure ship March 2026'!A:C,3,false) -> LBS | F19: 15589 | G19: =VLOOKUP(F19,'FML March 2026'!E:F,2,false) -> CHAYOTE, SELECT, 48CT 40#/CS | H19: =VLOOKUP(F19,'Unit of Measure ship March 2026'!A:C,3,false) -> LBS | J19: 14573 | K19: =VLOOKUP(J19,'FML March 2026'!E:F,2,false) -> DUCK WHOLE GRADE, "A" 4.00 - 5.0LB CS6/PC | L19: =VLOOKUP(J19,'Unit of Measure ship March 2026'!A:C,3,false) -> LBS
B20: 16579 | C20: =VLOOKUP(B20,'FML March 2026'!E:F,2,false) -> BEANS RED KIDNEY DARK 6/10 CANS (SPAIN) | D20: =VLOOKUP(B20,'Unit of Measure ship March 2026'!A:C,3,false) -> CN/6.5LB | F20: 15543 | G20: =VLOOKUP(F20,'FML March 2026'!E:F,2,false) -> CHERVIL, FRESH, 12BU 1 LB/CS | H20: =VLOOKUP(F20,'Unit of Measure ship March 2026'!A:C,3,false) -> LBS | J20: 14407 | K20: =VLOOKUP(J20,'FML March 2026'!E:F,2,false) -> LAMB LEGS BONELESS ROLLED & TIED FROZEN VAC-PAC (AUSTRALIA) | L20: =VLOOKUP(J20,'Unit of Measure ship March 2026'!A:C,3,false) -> LBS
B21: 16530 | C21: =VLOOKUP(B21,'FML March 2026'!E:F,2,false) -> BEANS, BAKED, VEGETARIAN, DRY, 6/#10 | D21: =VLOOKUP(B21,'Unit of Measure ship March 2026'!A:C,3,false) -> CN/6.5LB | F21: 35188 | G21: =VLOOKUP(F21,'FML March 2026'!E:F,2,false) -> CHILI PEPPERS RED FRESH | H21: =VLOOKUP(F21,'Unit of Measure ship March 2026'!A:C,3,false) -> LBS | J21: 14424 | K21: =VLOOKUP(J21,'FML March 2026'!E:F,2,false) -> LAMB SHOULDER SQUARE CUT NECK-ON FROZEN (AUSTRALIA) | L21: =VLOOKUP(J21,'Unit of Measure ship March 2026'!A:C,3,false) -> LBS
B22: 24910 | C22: =VLOOKUP(B22,'FML March 2026'!E:F,2,false) -> BEANS, PINTO DRY (VV) | D22: =VLOOKUP(B22,'Unit of Measure ship March 2026'!A:C,3,false) -> LBS | F22: 15438 | G22: =VLOOKUP(F22,'FML March 2026'!E:F,2,false) -> CHIVES (12 BUNCH), 1 LB/CS | H22: =VLOOKUP(F22,'Unit of Measure ship March 2026'!A:C,3,false) -> LBS | J22: 24773 | K22: =VLOOKUP(J22,'FML March 2026'!E:F,2,false) -> PORK BELLY RAW RIND-ON (USA) | L22: =VLOOKUP(J22,'Unit of Measure ship March 2026'!A:C,3,false) -> LBS
B23: 100449 | C23: =VLOOKUP(B23,'FML March 2026'!E:F,2,false) -> BEEF SAUCE BASE CREW/ STAFF | D23: =VLOOKUP(B23,'Unit of Measure ship March 2026'!A:C,3,false) -> LBS | F23: 15431 | G23: =VLOOKUP(F23,'FML March 2026'!E:F,2,false) -> CILANTRO (12 BUNCH) 1 LB/CS DOMESTIC | H23: =VLOOKUP(F23,'Unit of Measure ship March 2026'!A:C,3,false) -> LBS | J23: 14443 | K23: =VLOOKUP(J23,'FML March 2026'!E:F,2,false) -> PORK LOIN BACK RIBS 1-1/2# DOWN DOMESTIC NAMP 422 (USA) | L23: =VLOOKUP(J23,'Unit of Measure ship March 2026'!A:C,3,false) -> LBS
B24: 40504 | C24: =VLOOKUP(B24,'FML March 2026'!E:F,2,false) -> BEETS SLICED 3KG | D24: =VLOOKUP(B24,'Unit of Measure ship March 2026'!A:C,3,false) -> CAN/3KG | F24: 15619 | G24: =VLOOKUP(F24,'FML March 2026'!E:F,2,false) -> DAIKON 20#/CS | H24: =VLOOKUP(F24,'Unit of Measure ship March 2026'!A:C,3,false) -> LBS | J24: 11681 | K24: =VLOOKUP(J24,'FML March 2026'!E:F,2,false) -> PORK LOIN SMOKED CENTER CUT BONELESS (USA) | L24: =VLOOKUP(J24,'Unit of Measure ship March 2026'!A:C,3,false) -> LBS
B25: 53695 | C25: =VLOOKUP(B25,'FML March 2026'!E:F,2,false) -> BEV BASE, ORANGE, 45%, NESTLE - VITALITY, 12560122, FZN, 12/32 OZ | D25: =VLOOKUP(B25,'Unit of Measure ship March 2026'!A:C,3,false) -> PC/64OZ | F25: 15433 | G25: =VLOOKUP(F25,'FML March 2026'!E:F,2,false) -> DILL | H25: =VLOOKUP(F25,'Unit of Measure ship March 2026'!A:C,3,false) -> LBS | J25: 14399 | K25: =VLOOKUP(J25,'FML March 2026'!E:F,2,false) -> PORK LOIN WHOLE CRYOVAC 22-24 DOWN BONE IN, NAMP411 (USA) | L25: =VLOOKUP(J25,'Unit of Measure ship March 2026'!A:C,3,false) -> LBS
B26: 15178 | C26: =VLOOKUP(B26,'FML March 2026'!E:F,2,false) -> BLACKBERRIES, WHOLE, IQF, FRZN | D26: =VLOOKUP(B26,'Unit of Measure ship March 2026'!A:C,3,false) -> LBS | F26: 15508 | G26: =VLOOKUP(F26,'FML March 2026'!E:F,2,false) -> FINGERLING POTATOES | H26: =VLOOKUP(F26,'Unit of Measure ship March 2026'!A:C,3,false) -> LBS | J26: 10533 | K26: =VLOOKUP(J26,'FML March 2026'!E:F,2,false) -> PORK SHOULDER BUTT BONELESS | L26: =VLOOKUP(J26,'Unit of Measure ship March 2026'!A:C,3,false) -> LBS
B27: 43801 | C27: =VLOOKUP(B27,'FML March 2026'!E:F,2,false) -> BRUSSEL SPROUTS, MEDIUM, GRADE A, FRZN | D27: =VLOOKUP(B27,'Unit of Measure ship March 2026'!A:C,3,false) -> LBS | F27: 30479 | G27: =VLOOKUP(F27,'FML March 2026'!E:F,2,false) -> GALANGAL | H27: =VLOOKUP(F27,'Unit of Measure ship March 2026'!A:C,3,false) -> LBS | J27: 14397 | K27: =VLOOKUP(J27,'FML March 2026'!E:F,2,false) -> PORK SPARE RIBS 4-1/2 - DOWN 30# NAMP416 HATFIELD 1252 (USA) | L27: =VLOOKUP(J27,'Unit of Measure ship March 2026'!A:C,3,false) -> LBS
B28: 15016 | C28: =VLOOKUP(B28,'FML March 2026'!E:F,2,false) -> BUTTER, UNSALTED, 82% FAT, FZN, 50/200 G | D28: =VLOOKUP(B28,'Unit of Measure ship March 2026'!A:C,3,false) -> LBS | F28: 61703 | G28: =VLOOKUP(F28,'FML March 2026'!E:F,2,false) -> HABANERO PEPPERS FRESH | H28: =VLOOKUP(F28,'Unit of Measure ship March 2026'!A:C,3,false) -> LBS | J28: 14400 | K28: =VLOOKUP(J28,'FML March 2026'!E:F,2,false) -> PORK, HAM LEG, BONE IN, SHORT SHANK, SKIN ON, FRESH, NAMP 401A, >23 LB EA, FZN | L28: =VLOOKUP(J28,'Unit of Measure ship March 2026'!A:C,3,false) -> LBS
B29: 16290 | C29: =VLOOKUP(B29,'FML March 2026'!E:F,2,false) -> CAJUN SEASONING BADIA (USA ) | D29: =VLOOKUP(B29,'Unit of Measure ship March 2026'!A:C,3,false) -> LBS | F29: 15463 | G29: =VLOOKUP(F29,'FML March 2026'!E:F,2,false) -> JICAMA FRESH | H29: =VLOOKUP(F29,'Unit of Measure ship March 2026'!A:C,3,false) -> LBS | J29: 14524 | K29: =VLOOKUP(J29,'FML March 2026'!E:F,2,false) -> TURKEY BREAST RAW BONE-IN WHOLE SKIN-ON, USDA "A" 8/10 LB AVG (USA) | L29: =VLOOKUP(J29,'Unit of Measure ship March 2026'!A:C,3,false) -> LBS
B30: 11938 | C30: =VLOOKUP(B30,'FML March 2026'!E:F,2,false) -> CAPER BERRIES STEMMED 6/64 OZ DEL DESTINO/ ROLAND | D30: =VLOOKUP(B30,'Unit of Measure ship March 2026'!A:C,3,false) -> CAN/64OZ | F30: 30025 | G30: =VLOOKUP(F30,'FML March 2026'!E:F,2,false) -> KAFFIR LIME LEAVES FRESH | H30: =VLOOKUP(F30,'Unit of Measure ship March 2026'!A:C,3,false) -> LBS | J30: 14577 | K30: =VLOOKUP(J30,'FML March 2026'!E:F,2,false) -> TURKEYS WHOLE 20/22 OR 22/24 LB GRADE "A" (USA) | L30: =VLOOKUP(J30,'Unit of Measure ship March 2026'!A:C,3,false) -> LBS
B31: 16015 | C31: =VLOOKUP(B31,'FML March 2026'!E:F,2,false) -> CAPERS, NON-PAREIL, IN VINEGAR, DRY, 6X850GR | D31: =VLOOKUP(B31,'Unit of Measure ship March 2026'!A:C,3,false) -> CAN/32OZ | F31: 15395 | G31: =VLOOKUP(F31,'FML March 2026'!E:F,2,false) -> KIWI, NEW ZEALAND/CALIFORNIA, RIPE | H31: =VLOOKUP(F31,'Unit of Measure ship March 2026'!A:C,3,false) -> LBS
B32: 16309 | C32: =VLOOKUP(B32,'FML March 2026'!E:F,2,false) -> CARDAMOM GROUND | D32: =VLOOKUP(B32,'Unit of Measure ship March 2026'!A:C,3,false) -> LBS | F32: 15498 | G32: =VLOOKUP(F32,'FML March 2026'!E:F,2,false) -> LETTUCE GREEN LEAF CAL. 24HD 20#/CS | H32: =VLOOKUP(F32,'Unit of Measure ship March 2026'!A:C,3,false) -> LBS
B33: 43802 | C33: =VLOOKUP(B33,'FML March 2026'!E:F,2,false) -> CAULIFLOWER, FLORETS, GRADE A, IQF, FZN, 1/10 KG | D33: =VLOOKUP(B33,'Unit of Measure ship March 2026'!A:C,3,false) -> LBS | F33: 108947 | G33: =VLOOKUP(F33,'FML March 2026'!E:F,2,false) -> LIMES, FRESH, CAVIAR (FINGER LIMES) | H33: =VLOOKUP(F33,'Unit of Measure ship March 2026'!A:C,3,false) -> LBS
B34: 35186 | C34: =VLOOKUP(B34,'FML March 2026'!E:F,2,false) -> CELERY SALT 32 OZ D`ALLESANDRO/ SPICE CO | D34: =VLOOKUP(B34,'Unit of Measure ship March 2026'!A:C,3,false) -> JAR/32OZ | F34: 15434 | G34: =VLOOKUP(F34,'FML March 2026'!E:F,2,false) -> MARJORAM (12 BUNCH), 1 LB/CS | H34: =VLOOKUP(F34,'Unit of Measure ship March 2026'!A:C,3,false) -> LBS
B35: 11957 | C35: =VLOOKUP(B35,'FML March 2026'!E:F,2,false) -> CELERY SEEDS WHOLE 16 OZ D`ALLESANDRO/ SPICE CO | D35: =VLOOKUP(B35,'Unit of Measure ship March 2026'!A:C,3,false) -> LBS | F35: 15404 | G35: =VLOOKUP(F35,'FML March 2026'!E:F,2,false) -> MELON HONEYDEW #1 6/8CT. 25# | H35: =VLOOKUP(F35,'Unit of Measure ship March 2026'!A:C,3,false) -> LBS
B36: 48393 | C36: =VLOOKUP(B36,'FML March 2026'!E:F,2,false) -> CHAAT MASALA POWDER, INDIAN SPICE 10/100 GR MDH/SHAN | D36: =VLOOKUP(B36,'Unit of Measure ship March 2026'!A:C,3,false) -> LBS | F36: 15436 | G36: =VLOOKUP(F36,'FML March 2026'!E:F,2,false) -> MINT (12 BUNCH), 1 LB/CS | H36: =VLOOKUP(F36,'Unit of Measure ship March 2026'!A:C,3,false) -> LBS
B37: 14984 | C37: =VLOOKUP(B37,'FML March 2026'!E:F,2,false) -> CHEDDAR BLOCK YELLOW IMP.4/11 | D37: =VLOOKUP(B37,'Unit of Measure ship March 2026'!A:C,3,false) -> LBS | F37: 15556 | G37: =VLOOKUP(F37,'FML March 2026'!E:F,2,false) -> MUSHROOMS SHIITAKE FRESH NO 1 | H37: =VLOOKUP(F37,'Unit of Measure ship March 2026'!A:C,3,false) -> LBS
B38: 16308 | C38: =VLOOKUP(B38,'FML March 2026'!E:F,2,false) -> CHILI PEPPER RED CRUSHED D`ALLESANDRO/ SPICECO | D38: =VLOOKUP(B38,'Unit of Measure ship March 2026'!A:C,3,false) -> LBS | F38: 15496 | G38: =VLOOKUP(F38,'FML March 2026'!E:F,2,false) -> ONIONS RED, MEDIUM 25# | H38: =VLOOKUP(F38,'Unit of Measure ship March 2026'!A:C,3,false) -> LBS
B39: 16252 | C39: =VLOOKUP(B39,'FML March 2026'!E:F,2,false) -> CHILI POWDER 16 OZ D`ALLESANDRO/ SPICECO | D39: =VLOOKUP(B39,'Unit of Measure ship March 2026'!A:C,3,false) -> LBS | F39: 15447 | G39: =VLOOKUP(F39,'FML March 2026'!E:F,2,false) -> OREGANO FRESH | H39: =VLOOKUP(F39,'Unit of Measure ship March 2026'!A:C,3,false) -> LBS
B40: 16265 | C40: =VLOOKUP(B40,'FML March 2026'!E:F,2,false) -> CHINESE FIVE SPICE 16 OZ D`ALLESANDRO/ SPICECO | D40: =VLOOKUP(B40,'Unit of Measure ship March 2026'!A:C,3,false) -> LBS | F40: 105768 | G40: =VLOOKUP(F40,'FML March 2026'!E:F,2,false) -> PAPAYA (9-12CT), GREEN | H40: LBS
B41: 16253 | C41: =VLOOKUP(B41,'FML March 2026'!E:F,2,false) -> CINNAMON GROUND | D41: =VLOOKUP(B41,'Unit of Measure ship March 2026'!A:C,3,false) -> LBS | F41: 23714 | G41: =VLOOKUP(F41,'FML March 2026'!E:F,2,false) -> PARSNIP 20#/CS | H41: =VLOOKUP(F41,'Unit of Measure ship March 2026'!A:C,3,false) -> LBS
B42: 16267 | C42: =VLOOKUP(B42,'FML March 2026'!E:F,2,false) -> CINNAMON STICKS BADIA (USA) | D42: =VLOOKUP(B42,'Unit of Measure ship March 2026'!A:C,3,false) -> LBS | F42: 15501 | G42: =VLOOKUP(F42,'FML March 2026'!E:F,2,false) -> PEPPERS GREEN, MEDIUM, CHOICE, 88-100 MM | H42: =VLOOKUP(F42,'Unit of Measure ship March 2026'!A:C,3,false) -> LBS
B43: 16085 | C43: =VLOOKUP(B43,'FML March 2026'!E:F,2,false) -> CLAM JUICE BLENDED 12/46OZ (USA) | D43: =VLOOKUP(B43,'Unit of Measure ship March 2026'!A:C,3,false) -> CN/46OZ | F43: 15504 | G43: =VLOOKUP(F43,'FML March 2026'!E:F,2,false) -> PEPPERS HOT, JALAPENOS 10# | H43: =VLOOKUP(F43,'Unit of Measure ship March 2026'!A:C,3,false) -> LBS
...

Sheet 08 Special Service Food
B1: 08 - Special Service Food - Crew Party Food 01/08/01 | F1: 08 - Special Service Food - Guest Special Request Food 01/08/02
B2: Code | C2: Ingredient Name | D2: UM | F2: Code | G2: Ingredient Name | H2: UM

Sheet 13 Test Kitchen
B1: 13 - The Test Kitchen - Menu Basic Preperation 01/13/01 | F1: 13 - The Test Kitchen - Vegetables & Fruits 03/13/06 | J1: 13 - The Test Kitchen - Meat 05/13/03 | N1: 13 - The Test Kitchen - Fish & Seafood 05/13/04
B2: Code | C2: Ingredient Name | D2: UM | F2: Code | G2: Ingredient Name | H2: UM | J2: Code | K2: Ingredient Name | L2: UM | N2: Code | O2: Ingredient Name | P2: UM
B3: 51236 | C3: =VLOOKUP(B3,'FML March 2026'!E:F,2,false) -> ACID CITRIC 1 KG L. FRANCOIS CUISINE TECH | D3: =VLOOKUP(B3,'Unit of Measure ship March 2026'!A:C,3,false) -> LBS | F3: 53697 | G3: =VLOOKUP(F3,'FML March 2026'!E:F,2,false) -> ARTICHOKE, JERUSALEM, FRESH | H3: =VLOOKUP(F3,'Unit of Measure ship March 2026'!A:C,3,false) -> LBS | J3: 148887 | K3: =VLOOKUP(J3,'FML March 2026'!E:F,2,false) -> BEEF TENDERLOIN PEELED STRAP-ON 100 DAY GRAIN FED JBS (AUSTRALIA) NAMP-189A | L3: =VLOOKUP(J3,'Unit of Measure ship March 2026'!A:C,3,false) -> LBS | N3: 10052 | O3: =VLOOKUP(N3,'FML March 2026'!E:F,2,false) -> COD FILLET BERING SEA 16/32 OZ FROZEN (PCH) (CHINA) | P3: =VLOOKUP(N3,'Unit of Measure ship March 2026'!A:C,3,false) -> LBS
B4: 16211 | C4: =VLOOKUP(B4,'FML March 2026'!E:F,2,false) -> AGAR AGAR POWDER CUISINE TECH | D4: =VLOOKUP(B4,'Unit of Measure ship March 2026'!A:C,3,false) -> LBS | F4: 11843 | G4: =VLOOKUP(F4,'FML March 2026'!E:F,2,false) -> ASPARAGUS WHITE FRESH | H4: =VLOOKUP(F4,'Unit of Measure ship March 2026'!A:C,3,false) -> LBS | J4: 14386 | K4: =VLOOKUP(J4,'FML March 2026'!E:F,2,false) -> CALVES FEET 35# PACKED W PLASTIC WRAP | L4: =VLOOKUP(J4,'Unit of Measure ship March 2026'!A:C,3,false) -> PC | N4: 148490 | O4: =VLOOKUP(N4,'FML March 2026'!E:F,2,false) -> GRILLED EEL/ UNAGI/ KABAYAKI (BBQ EEL SUSHI) | P4: =VLOOKUP(N4,'Unit of Measure ship March 2026'!A:C,3,false) -> LBS
B5: 16262 | C5: =VLOOKUP(B5,'FML March 2026'!E:F,2,false) -> ALLSPICE BADIA | D5: =VLOOKUP(B5,'Unit of Measure ship March 2026'!A:C,3,false) -> LBS | F5: 15572 | G5: =VLOOKUP(F5,'FML March 2026'!E:F,2,false) -> ASPARAGUS, FRESH, LARGE, FULL 11# BOX, 17 PC/BOX | H5: =VLOOKUP(F5,'Unit of Measure ship March 2026'!A:C,3,false) -> LBS | J5: 108520 | K5: =VLOOKUP(J5,'FML March 2026'!E:F,2,false) -> CHICKEN WHOLE ANTIBIOTIC-FREE (NAKED) JOYCE FARMS | L5: =VLOOKUP(J5,'Unit of Measure ship March 2026'!A:C,3,false) -> LBS | N5: 53625 | O5: =VLOOKUP(N5,'FML March 2026'!E:F,2,false) -> SALMON FILLET, ATLANTIC, PREMIUM, FROZEN, 3 - 4 LB D-TRIM INDV. CRYOVAC (CHILE) | P5: =VLOOKUP(N5,'Unit of Measure ship March 2026'!A:C,3,false) -> LBS
B6: 110967 | C6: =VLOOKUP(B6,'FML March 2026'!E:F,2,false) -> ALMONDS HICKORY SMOKED CS9/9OZ BACK TO NATURE SMOKED | D6: =VLOOKUP(B6,'Unit of Measure ship March 2026'!A:C,3,false) -> LBS | F6: 15429 | G6: =VLOOKUP(F6,'FML March 2026'!E:F,2,false) -> BASIL (12 BUNCH) HYDROPONIC OR REGULAR 1 LB/CS | H6: =VLOOKUP(F6,'Unit of Measure ship March 2026'!A:C,3,false) -> LBS | J6: 14576 | K6: =VLOOKUP(J6,'FML March 2026'!E:F,2,false) -> CHICKEN, FRYER, WOG, IND WRAPPED, NON-INJECTED, 2.50-3.25 LB EA, FZN, 12/1 EA | L6: =VLOOKUP(J6,'Unit of Measure ship March 2026'!A:C,3,false) -> LBS | N6: 102829 | O6: =VLOOKUP(N6,'FML March 2026'!E:F,2,false) -> Scallops 10/15 CT | P6: =VLOOKUP(N6,'Unit of Measure ship March 2026'!A:C,3,false) -> LBS
B7: 109664 | C7: =VLOOKUP(B7,'FML March 2026'!E:F,2,false) -> APPLE CIDER VINEGAR SPARROW LANE V | D7: =VLOOKUP(B7,'Unit of Measure ship March 2026'!A:C,3,false) -> GAL | F7: 111119 | G7: =VLOOKUP(F7,'FML March 2026'!E:F,2,false) -> BASIL BLOSSOMS FRESH TRAY 6/POTS HARPKE FARMS | H7: =VLOOKUP(F7,'Unit of Measure ship March 2026'!A:C,3,false) -> LBS | J7: 27414 | K7: =VLOOKUP(J7,'FML March 2026'!E:F,2,false) -> LAMB RACKS CAPOFF FRENCHED 20/28 OZ FROZEN INDV VAC PAC (NEW ZEALAND/AUSTRALIA) | L7: =VLOOKUP(J7,'Unit of Measure ship March 2026'!A:C,3,false) -> LBS | N7: 42269 | O7: =VLOOKUP(N7,'FML March 2026'!E:F,2,false) -> SHRIMP 16/20 RAW P&D TAIL-ON CS10/LB SURAM ROYAL WHITE (VIETNAM) | P7: =VLOOKUP(N7,'Unit of Measure ship March 2026'!A:C,3,false) -> LBS
B8: 109223 | C8: =VLOOKUP(B8,'FML March 2026'!E:F,2,false) -> AQUAFABA POWDER EGG REPLACER SAHELI PK 300GR | D8: =VLOOKUP(B8,'Unit of Measure ship March 2026'!A:C,3,false) -> LBS | F8: 15449 | G8: =VLOOKUP(F8,'FML March 2026'!E:F,2,false) -> BEET ROOTS LARGE 1/25# | H8: =VLOOKUP(F8,'Unit of Measure ship March 2026'!A:C,3,false) -> LBS | J8: 42345 | K8: =VLOOKUP(J8,'FML March 2026'!E:F,2,false) -> VENISON, STRIPLOIN, BONELESS, DENUDED, 4-6 LB EA, FZN | L8: =VLOOKUP(J8,'Unit of Measure ship March 2026'!A:C,3,false) -> LBS
B9: 15651 | C9: =VLOOKUP(B9,'FML March 2026'!E:F,2,false) -> BAKING POWDER 50 LB | D9: =VLOOKUP(B9,'Unit of Measure ship March 2026'!A:C,3,false) -> LBS | F9: 15335 | G9: =VLOOKUP(F9,'FML March 2026'!E:F,2,false) -> BLUEBERRIES FRESH 12 1/2 PT 4.5# | H9: =VLOOKUP(F9,'Unit of Measure ship March 2026'!A:C,3,false) -> LBS
B10: 15652 | C10: =VLOOKUP(B10,'FML March 2026'!E:F,2,false) -> BAKING SODA | D10: =VLOOKUP(B10,'Unit of Measure ship March 2026'!A:C,3,false) -> LBS | F10: 15458 | G10: =VLOOKUP(F10,'FML March 2026'!E:F,2,false) -> CARROTS CLIP TOP 50# | H10: =VLOOKUP(F10,'Unit of Measure ship March 2026'!A:C,3,false) -> LBS
B11: 16182 | C11: =VLOOKUP(B11,'FML March 2026'!E:F,2,false) -> BARLEY PEARLED | D11: =VLOOKUP(B11,'Unit of Measure ship March 2026'!A:C,3,false) -> LBS | F11: 110917 | G11: =VLOOKUP(F11,'FML March 2026'!E:F,2,false) -> CAULIFLOWER ORANGE 12CT (28LB) | H11: =VLOOKUP(F11,'Unit of Measure ship March 2026'!A:C,3,false) -> LBS
B12: 110934 | C12: =VLOOKUP(B12,'FML March 2026'!E:F,2,false) -> BASIL SEEDS PKG 1 LB KALUSTYANS | D12: =VLOOKUP(B12,'Unit of Measure ship March 2026'!A:C,3,false) -> LBS | F12: 15562 | G12: =VLOOKUP(F12,'FML March 2026'!E:F,2,false) -> CELERIAC (CELERY ROOT) 20# | H12: =VLOOKUP(F12,'Unit of Measure ship March 2026'!A:C,3,false) -> LBS
B13: 16250 | C13: =VLOOKUP(B13,'FML March 2026'!E:F,2,false) -> BAY LEAVES WHOLE D`ALLESANDRO/ SPICECO | D13: =VLOOKUP(B13,'Unit of Measure ship March 2026'!A:C,3,false) -> LBS | F13: 15460 | G13: =VLOOKUP(F13,'FML March 2026'!E:F,2,false) -> CELERY #1 CAL. 36CT 60# | H13: =VLOOKUP(F13,'Unit of Measure ship March 2026'!A:C,3,false) -> LBS
B14: 109712 | C14: =VLOOKUP(B14,'FML March 2026'!E:F,2,false) -> BREAD SOURDOUGH COUNTRY WHEAT BRD40B19 1KG LOAF ZAK THE BAKER | D14: =VLOOKUP(B14,'Unit of Measure ship March 2026'!A:C,3,false) -> LV | F14: 109760 | G14: =VLOOKUP(F14,'FML March 2026'!E:F,2,false) -> CELERY MICRO HARPKE FAMILY FARM - PK/5 OZ PACKED IN 60 OZ CLAM SHELL | H14: =VLOOKUP(F14,'Unit of Measure ship March 2026'!A:C,3,false) -> PK/5OZ
B15: 16981 | C15: =VLOOKUP(B15,'FML March 2026'!E:F,2,false) -> BRIE MON PERE 60% 3KG / DEXPA # 53726 | D15: =VLOOKUP(B15,'Unit of Measure ship March 2026'!A:C,3,false) -> LBS | F15: 15543 | G15: =VLOOKUP(F15,'FML March 2026'!E:F,2,false) -> CHERVIL, FRESH, 12BU 1 LB/CS | H15: =VLOOKUP(F15,'Unit of Measure ship March 2026'!A:C,3,false) -> LBS
B16: 109933 | C16: =VLOOKUP(B16,'FML March 2026'!E:F,2,false) -> BUTTER ALTERNATIVE VEGAN PLANT PERFECT (USA) | D16: =VLOOKUP(B16,'Unit of Measure ship March 2026'!A:C,3,false) -> LBS | F16: 15438 | G16: =VLOOKUP(F16,'FML March 2026'!E:F,2,false) -> CHIVES (12 BUNCH), 1 LB/CS | H16: =VLOOKUP(F16,'Unit of Measure ship March 2026'!A:C,3,false) -> LBS
B17: 15016 | C17: =VLOOKUP(B17,'FML March 2026'!E:F,2,false) -> BUTTER, UNSALTED, 82% FAT, FZN, 50/200 G | D17: =VLOOKUP(B17,'Unit of Measure ship March 2026'!A:C,3,false) -> LBS | F17: 15431 | G17: =VLOOKUP(F17,'FML March 2026'!E:F,2,false) -> CILANTRO (12 BUNCH) 1 LB/CS DOMESTIC | H17: =VLOOKUP(F17,'Unit of Measure ship March 2026'!A:C,3,false) -> LBS
B18: 43176 | C18: =VLOOKUP(B18,'FML March 2026'!E:F,2,false) -> BUTTER, UNSALTED, 84% FAT, EXTRA DRY, SHEETED, CROISSANT, FZN, 5/2 KG | D18: =VLOOKUP(B18,'Unit of Measure ship March 2026'!A:C,3,false) -> KG | F18: 111175 | G18: =VLOOKUP(F18,'FML March 2026'!E:F,2,false) -> CILANTRO MICRO FRESH HARPKE FAMILY FARM PK/5 OZ PACKED IN 60 OZ SIZE CLAM SHELL | H18: =VLOOKUP(F18,'Unit of Measure ship March 2026'!A:C,3,false) -> EA
B19: 14893 | C19: =VLOOKUP(B19,'FML March 2026'!E:F,2,false) -> BUTTERMILK LOCAL 10 DAYS CS9/HGAL | D19: =VLOOKUP(B19,'Unit of Measure ship March 2026'!A:C,3,false) -> QRT | F19: 10013 | G19: =VLOOKUP(F19,'FML March 2026'!E:F,2,false) -> CORN ON THE COB FRESH | H19: =VLOOKUP(F19,'Unit of Measure ship March 2026'!A:C,3,false) -> LBS
B20: 15893 | C20: =VLOOKUP(B20,'FML March 2026'!E:F,2,false) -> CASHEWS, RAW, WHOLE, #320, DRY, 1/50 LB | D20: =VLOOKUP(B20,'Unit of Measure ship March 2026'!A:C,3,false) -> LBS | F20: 109754 | G20: =VLOOKUP(F20,'FML March 2026'!E:F,2,false) -> CUCUMBER ENGLISH SEEDLESS, LARGE | H20: =VLOOKUP(F20,'Unit of Measure ship March 2026'!A:C,3,false) -> LBS
... B77: 16305 | C77: =VLOOKUP(B77,'FML March 2026'!E:F,2,false) -> PEPPERCORN WHITE WHOLE D`ALLESANDRO/ SPICECO | D77: =VLOOKUP(B77,'Unit of Measure ship March 2026'!A:C,3,false) -> LBS | F77: 15542 | G77: =VLOOKUP(F77,'FML March 2026'!E:F,2,false) -> ZUCCHINI MEDIUM #1 FANCY 20#/CS, 180-210 MM | H77: =VLOOKUP(F77,'Unit of Measure ship March 2026'!A:C,3,false) -> LBS
B78: 16285 | C78: =VLOOKUP(B78,'FML March 2026'!E:F,2,false) -> PEPPERCORN, BLACK, WHOLE, DRY, 6/420 G | D78: =VLOOKUP(B78,'Unit of Measure ship March 2026'!A:C,3,false) -> LBS
B79: 47893 | C79: =VLOOKUP(B79,'FML March 2026'!E:F,2,false) -> PICKLES KOSHER DRY B&G (USA) | D79: =VLOOKUP(B79,'Unit of Measure ship March 2026'!A:C,3,false) -> GAL
B80: 15894 | C80: =VLOOKUP(B80,'FML March 2026'!E:F,2,false) -> PISTACHIO NUTS WHOLE SHELLED RAW NUTLAND | D80: =VLOOKUP(B80,'Unit of Measure ship March 2026'!A:C,3,false) -> LBS
B81: 14967 | C81: =VLOOKUP(B81,'FML March 2026'!E:F,2,false) -> PLAIN PLANT BASED YOGURT (BULK PACK) | D81: =VLOOKUP(B81,'Unit of Measure ship March 2026'!A:C,3,false) -> PC24/OZ
B82: 16885 | C82: =VLOOKUP(B82,'FML March 2026'!E:F,2,false) -> POPCORN KERNELS YELLOW 50LB PACKER (USA) | D82: =VLOOKUP(B82,'Unit of Measure ship March 2026'!A:C,3,false) -> LBS
B83: 110935 | C83: =VLOOKUP(B83,'FML March 2026'!E:F,2,false) -> PORCINI POWDER | D83: =VLOOKUP(B83,'Unit of Measure ship March 2026'!A:C,3,false) -> LBS
B84: 14541 | C84: =VLOOKUP(B84,'FML March 2026'!E:F,2,false) -> PORK, BACON, SLICED, APPLEWOOD SMOKED, LAID OUT, 18-22/LB, FZN, 1/15 LB | D84: =VLOOKUP(B84,'Unit of Measure ship March 2026'!A:C,3,false) -> LBS
B85: 14541 | C85: =VLOOKUP(B85,'FML March 2026'!E:F,2,false) -> PORK, BACON, SLICED, APPLEWOOD SMOKED, LAID OUT, 18-22/LB, FZN, 1/15 LB | D85: =VLOOKUP(B85,'Unit of Measure ship March 2026'!A:C,3,false) -> LBS
B86: 101442 | C86: =VLOOKUP(B86,'FML March 2026'!E:F,2,false) -> PROSCIUTTO DI SAN DANIELE LEVONI BONELESS 16 MONTH RESERVE CS/16 LBS | D86: =VLOOKUP(B86,'Unit of Measure ship March 2026'!A:C,3,false) -> LBS
B87: 15897 | C87: =VLOOKUP(B87,'FML March 2026'!E:F,2,false) -> PUMPKIN SEEDS WHOLE SHELLED RAW 10 LB HIALEAH/ D`ALLESANDRO | D87: =VLOOKUP(B87,'Unit of Measure ship March 2026'!A:C,3,false) -> LBS
B88: 16946 | C88: =VLOOKUP(B88,'FML March 2026'!E:F,2,false) -> QUINOA WHITE | D88: =VLOOKUP(B88,'Unit of Measure ship March 2026'!A:C,3,false) -> PC/12OZ
B89: 142891 | C89: =VLOOKUP(B89,'FML March 2026'!E:F,2,false) -> SALT CURING PRAGUE #1 2.5 LB HOOSIER HILL | D89: =VLOOKUP(B89,'Unit of Measure ship March 2026'!A:C,3,false) -> LBS
... B124: 19409 | C124: =VLOOKUP(B124,'FML March 2026'!E:F,2,false) -> YUZU JUICE PURE UNSEASONED SHIBORI YAKAMI ORCHARD | D124: =VLOOKUP(B124,'Unit of Measure ship March 2026'!A:C,3,false) -> BT/750ML

Sheet 14 Pink Agave
B1: 14 - Pink Agave - Menu Basic Preperation 01/14/01 | F1: 14 - Pink Agave - Fruit & Vegetables 03/14/06 | J1: 14 - Pink Agave - Meat 05/14/03 | N1: 14 - Pink Agave - Fish & Seafood 05/14/04
B2: Code | C2: Ingredient Name | D2: UM | F2: Code | G2: Ingredient Name | H2: UM | J2: Code | K2: Ingredient Name | L2: UM | N2: Code | O2: Ingredient Name | P2: UM
B3: 111691 | C3: =VLOOKUP(B3,'FML March 2026'!E:F,2,false) -> ACHIOTE PASTE CS 12/3.5OZ EL YUCATECO | D3: =VLOOKUP(B3,'Unit of Measure ship March 2026'!A:C,3,false) -> LBS | F3: 37612 | G3: =VLOOKUP(F3,'FML March 2026'!E:F,2,false) -> AMARANTH CRESS | H3: =VLOOKUP(F3,'Unit of Measure ship March 2026'!A:C,3,false) -> LBS | J3: 34727 | K3: =VLOOKUP(J3,'FML March 2026'!E:F,2,false) -> BEEF EXPORT RIBS, CAB CHOICE 18/DOWN 4/PC, 30D AGE,BLST/FRZN (USA) NAMP-109E | L3: =VLOOKUP(J3,'Unit of Measure ship March 2026'!A:C,3,false) -> LBS | N3: 42269 | O3: =VLOOKUP(N3,'FML March 2026'!E:F,2,false) -> SHRIMP 16/20 RAW P&D TAIL-ON CS10/LB SURAM ROYAL WHITE (VIETNAM) | P3: =VLOOKUP(#REF!,'Unit of Measure ship March 2026'!A:C,3,false) -> #REF!
B4: 16262 | C4: =VLOOKUP(B4,'FML March 2026'!E:F,2,false) -> ALLSPICE BADIA | D4: =VLOOKUP(B4,'Unit of Measure ship March 2026'!A:C,3,false) -> LBS | F4: 15378 | G4: =VLOOKUP(F4,'FML March 2026'!E:F,2,false) -> AVOCADOS HASS FRESH CA-48PC FL-12/14PC 20# | H4: =VLOOKUP(F4,'Unit of Measure ship March 2026'!A:C,3,false) -> LBS | J4: 14576 | K4: =VLOOKUP(J4,'FML March 2026'!E:F,2,false) -> CHICKEN, FRYER, WOG, IND WRAPPED, NON-INJECTED, 2.50-3.25 LB EA, FZN, 12/1 EA | L4: =VLOOKUP(J4,'Unit of Measure ship March 2026'!A:C,3,false) -> LBS | N4: 53677 | O4: =VLOOKUP(N4,'FML March 2026'!E:F,2,false) -> STRIPED BASS FILLET WILD SKIN-ON 2/3 LB IQFCS/25 LB | P4: =VLOOKUP(N3,'Unit of Measure ship March 2026'!A:C,3,false) -> LBS
B5: 16304 | C5: =VLOOKUP(B5,'FML March 2026'!E:F,2,false) -> ANISE STAR BADIA | D5: =VLOOKUP(B5,'Unit of Measure ship March 2026'!A:C,3,false) -> UNIT/8OZ | F5: 15605 | G5: =VLOOKUP(F5,'FML March 2026'!E:F,2,false) -> BEANS FRESH EXTRA FINE GREEN (FRENCH) 1/5 (HARICOT VERT) | H5: =VLOOKUP(F5,'Unit of Measure ship March 2026'!A:C,3,false) -> LBS | J5: 14573 | K5: =VLOOKUP(J5,'FML March 2026'!E:F,2,false) -> DUCK WHOLE GRADE, "A" 4.00 - 5.0LB CS6/PC | L5: =VLOOKUP(J5,'Unit of Measure ship March 2026'!A:C,3,false) -> LBS | N5: 14651 | O5: =VLOOKUP(N5,'FML March 2026'!E:F,2,false) -> TUNA LOIN SKINLESS FROZEN, (IP IS FTZ) (YEMEN) | P5: LBS
B6: 109664 | C6: =VLOOKUP(B6,'FML March 2026'!E:F,2,false) -> APPLE CIDER VINEGAR SPARROW LANE V | D6: =VLOOKUP(B6,'Unit of Measure ship March 2026'!A:C,3,false) -> GAL | F6: 111931 | G6: =VLOOKUP(F6,'FML March 2026'!E:F,2,false) -> CACTUS PEAR RED XOCONOSTLE 30/36 CT | H6: =VLOOKUP(F6,'Unit of Measure ship March 2026'!A:C,3,false) -> LBS | J6: 10533 | K6: =VLOOKUP(J6,'FML March 2026'!E:F,2,false) -> PORK SHOULDER BUTT BONELESS | L6: =VLOOKUP(J6,'Unit of Measure ship March 2026'!A:C,3,false) -> LBS
B7: 30023 | C7: =VLOOKUP(B7,'FML March 2026'!E:F,2,false) -> BANANA LEAVES, 30/1 LB, SUN VOI (THAILAND) | D7: =VLOOKUP(B7,'Unit of Measure ship March 2026'!A:C,3,false) -> LBS | F7: 15559 | G7: =VLOOKUP(F7,'FML March 2026'!E:F,2,false) -> CARROTS MINI W/TOPS, PEELED, 1/5LB, VAC. PACK | H7: =VLOOKUP(F7,'Unit of Measure ship March 2026'!A:C,3,false) -> LBS
B8: 16250 | C8: =VLOOKUP(B8,'FML March 2026'!E:F,2,false) -> BAY LEAVES WHOLE D`ALLESANDRO/ SPICECO | D8: =VLOOKUP(B8,'Unit of Measure ship March 2026'!A:C,3,false) -> LBS | F8: 15589 | G8: =VLOOKUP(F8,'FML March 2026'!E:F,2,false) -> CHAYOTE, SELECT, 48CT 40#/CS | H8: =VLOOKUP(F8,'Unit of Measure ship March 2026'!A:C,3,false) -> LBS
B9: 16178 | C9: =VLOOKUP(B9,'FML March 2026'!E:F,2,false) -> BEANS BLACK COMMERCIAL DE LEGUMBRES/ TORINO | D9: =VLOOKUP(B9,'Unit of Measure ship March 2026'!A:C,3,false) -> LBS | F9: 15431 | G9: =VLOOKUP(F9,'FML March 2026'!E:F,2,false) -> CILANTRO (12 BUNCH) 1 LB/CS DOMESTIC | H9: =VLOOKUP(F9,'Unit of Measure ship March 2026'!A:C,3,false) -> LBS
B10: 24910 | C10: =VLOOKUP(B10,'FML March 2026'!E:F,2,false) -> BEANS, PINTO DRY (VV) | D10: =VLOOKUP(B10,'Unit of Measure ship March 2026'!A:C,3,false) -> LBS | F10: 111175 | G10: =VLOOKUP(F10,'FML March 2026'!E:F,2,false) -> CILANTRO MICRO FRESH HARPKE FAMILY FARM PK/5 OZ PACKED IN 60 OZ SIZE CLAM SHELL | H10: =VLOOKUP(F10,'Unit of Measure ship March 2026'!A:C,3,false) -> EA
